<?xml version="1.0"?>
<robot xmlns:xacro="http://wiki.ros.org/xacro" name="kuka_kr210_r3100">

  <xacro:macro name="kuka_kr210_r3100" params="prefix">
    
    
      <!-- KR210_1 -->
  <joint name="kr210_${prefix}_linear_axis_joint" type="prismatic">
    <origin rpy="0 0 -1.5708" xyz="0 0 0.485"/>
    <parent link="linear_axis"/>
    <child link="KR210_1_socket"/>
    <axis xyz="-1.0 0.0 0.0"/>
    <limit effort="100" lower="-9" upper="0" velocity="100"/>
  </joint>
    
    
    
  <link name="KR210_${prefix}_socket">
    <visual>
      <origin rpy="0 0 0" xyz="0 0 0"/>
      <geometry>
        <mesh filename="package://tez_description/mesh/collada/reduced_details/KR210_3100_ultra_socket.dae"/>
      </geometry>
    </visual>
    <collision>
      <origin rpy="0 0 0" xyz="0 0 0"/>
      <geometry>
        <mesh filename="package://tez_description/mesh/collada/reduced_details/KR210_3100_ultra_socket.dae"/>
      </geometry>
    </collision>
  </link>

  <joint name="kr210_${prefix}_joint_1" type="revolute">
    <origin rpy="0 0 0" xyz="0 0 0.5256"/>
    <parent link="KR210_${prefix}_socket"/>
    <child link="KR210_${prefix}_A1"/>
    <axis xyz="0.0 0.0 1.0"/>
    <limit effort="100" lower="-3.22886" upper="3.22886" velocity="100"/>
  </joint>

  <link name="KR210_${prefix}_A1">
    <visual>
      <origin rpy="0 0 0" xyz="0 0 0"/>
      <geometry>
        <mesh filename="package://tez_description/mesh/collada/reduced_details/KR210_3100_ultra_A1.dae"/>
      </geometry>
    </visual>
    <collision>
      <origin rpy="0 0 0" xyz="0 0 0"/>
      <geometry>
        <mesh filename="package://tez_description/mesh/collada/reduced_details/KR210_3100_ultra_A1.dae"/>
      </geometry>
    </collision>
  </link>

  <joint name="kr210_${prefix}_joint_2" type="revolute">
    <origin rpy="0 0 0" xyz="0.005 -0.35 0.45"/>
    <parent link="KR210_${prefix}_A1"/>
    <child link="KR210_${prefix}_A2"/>
    <axis xyz="1.0 0.0 0.0"/>
    <limit effort="10000" lower="-2.0944" upper="1.22173" velocity="100"/>
  </joint>

  <link name="KR210_${prefix}_A2">
    <visual>
      <origin rpy="0 0 0" xyz="0 0 0"/>
      <geometry>
        <mesh filename="package://tez_description/mesh/collada/reduced_details/KR210_3100_ultra_A2.dae"/>
      </geometry>
    </visual>
    <collision>
      <origin rpy="0 0 0" xyz="0 0 0"/>
      <geometry>
        <mesh filename="package://tez_description/mesh/collada/reduced_details/KR210_3100_ultra_A2.dae"/>
      </geometry>
    </collision>
  </link>

  <joint name="kr210_${prefix}_joint_3" type="revolute">
    <origin rpy="0 0 0" xyz="-0.183 0 1.35"/>
    <parent link="KR210_${prefix}_A2"/>
    <child link="KR210_${prefix}_A3"/>
    <axis xyz="1.0 0.0 0.0"/>
    <limit effort="100" lower="-2.0944" upper="2.70526" velocity="100"/>
  </joint>

  <link name="KR210_${prefix}_A3">
    <visual>
      <origin rpy="0 0 0" xyz="0 0 0"/>
      <geometry>
        <mesh filename="package://tez_description/mesh/collada/reduced_details/KR210_3100_ultra_A3.dae"/>
      </geometry>
    </visual>
    <collision>
      <origin rpy="0 0 0" xyz="0 0 0"/>
      <geometry>
        <mesh filename="package://tez_description/mesh/collada/reduced_details/KR210_3100_ultra_A3.dae"/>
      </geometry>
    </collision>
  </link>

  <joint name="kr210_${prefix}_joint_4" type="revolute">
    <origin rpy="0 0 0" xyz="0.178 -0.962 -0.041"/>
    <parent link="KR210_${prefix}_A3"/>
    <child link="KR210_${prefix}_A4"/>
    <axis xyz="0.0 1.0 0.0"/>
    <limit effort="100" lower="-6.10865" upper="6.10865" velocity="100"/>
  </joint>

  <link name="KR210_${prefix}_A4">
    <visual>
      <origin rpy="0 0 0" xyz="0 0 0"/>
      <geometry>
        <mesh filename="package://tez_description/mesh/collada/reduced_details/KR210_3100_ultra_A4.dae"/>
      </geometry>
    </visual>
    <collision>
      <origin rpy="0 0 0" xyz="0 0 0"/>
      <geometry>
        <mesh filename="package://tez_description/mesh/collada/reduced_details/KR210_3100_ultra_A4.dae"/>
      </geometry>
    </collision>
  </link>

  <joint name="kr210_${prefix}_joint_5" type="revolute">
    <origin rpy="0 0 0" xyz="0 -0.438 0"/>
    <parent link="KR210_${prefix}_A4"/>
    <child link="KR210_${prefix}_A5"/>
    <axis xyz="1.0 0.0 0.0"/>
    <limit effort="100" lower="-2.18166" upper="2.18166" velocity="100"/>
  </joint>

  <link name="KR210_${prefix}_A5">
    <visual>
      <origin rpy="0 0 0" xyz="0 0 0"/>
      <geometry>
        <mesh filename="package://tez_description/mesh/collada/reduced_details/KR210_3100_ultra_A5.dae"/>
      </geometry>
    </visual>
    <collision>
      <origin rpy="0 0 0" xyz="0 0 0"/>
      <geometry>
        <mesh filename="package://tez_description/mesh/collada/reduced_details/KR210_3100_ultra_A5.dae"/>
      </geometry>
    </collision>
  </link>

  <joint name="kr210_${prefix}_joint_6" type="revolute">
    <origin rpy="0 0 0" xyz="0 -0.24 0"/>
    <parent link="KR210_${prefix}_A5"/>
    <child link="KR210_${prefix}_A6"/>
    <axis xyz="0.0 1.0 0.0"/>
    <limit effort="100" lower="-6.10865" upper="6.10865" velocity="2"/>
  </joint>

  <link name="KR210_${prefix}_A6">
    <visual>
      <origin rpy="0 0 0" xyz="0 0 0"/>
      <geometry>
        <mesh filename="package://tez_description/mesh/collada/reduced_details/KR210_3100_ultra_A6.dae"/>
      </geometry>
    </visual>
    <collision>
      <origin rpy="0 0 0" xyz="0 0 0"/>
      <geometry>
        <mesh filename="package://tez_description/mesh/collada/reduced_details/KR210_3100_ultra_A6.dae"/>
      </geometry>
    </collision>
  </link>
  
  </xacro:macro>
</robot>

